Workbook

Sheet Assumptions
A1: ASSUMPTIONS SHEET
A3: INCOME - HUSBAND
A4: Base Gross Salary (2026) | B4: 88397
A5: Salary Growth Rate | B5: 0.05
A6: Base Bonus (2026) | B6: 9821
A7: Bonus Growth Rate | B7: 0.05
A8: Monthly Time Account Deduction | B8: 200
A9: Bonus to Time Account % | B9: 0.35
A10: RSU Annual Grant | B10: 20000
A11: RSU Tax Rate | B11: 0.443
A12: Stock Price | B12: 210
A14: INCOME - WIFE
A15: Base Gross Salary (2026) | B15: 74348
A16: Salary Growth Rate | B16: 0.035
A17: Base Bonus (2026) | B17: 8261
A18: Bonus Growth Rate | B18: 0.035
A19: Monthly Time Account Deduction | B19: 200
A20: Bonus to Time Account % | B20: 0.35
A21: RSU Annual Grant | B21: 10000
A23: TIME ACCOUNT
A24: Starting Hours - Husband (Dec 2025) | B24: 1700
A25: Starting Hours - Wife (Dec 2025) | B25: 20
A26: Starting Hourly Rate (2026) | B26: 42.5
A27: Hourly Rate Growth | B27: 0.05
A28: Time Account Tax Haircut | B28: 0.35
A30: MORTGAGE
A31: Original Principal | B31: 431000
A32: Interest Rate | B32: 0.0389
A33: Monthly Payment | B33: 2281
A34: Max Sondertilgung (5%) | B34: 21550
A35: Start Month (Jun 2023) | B35: 1
A36: Maturity Month | B36: 120
A37: Balance after Nov 2025 | B37: 397546
A38: Sondertilgung Dec 2025 | B38: 0
A40: INVESTMENT
A41: Starting Balance (Dec 2025) | B41: 12000
A42: Annual Return | B42: 0.085
A43: Monthly Return Factor | B43: 1.006818
A44: Tax on Gains (Effective) | B44: 0.184625
A45: Monthly Salary Investment Start | B45: 1000
...

Sheet SL_Investment_Log
A1: ID | B1: Date | C1: MonthKey | D1: Amount | E1: Destination | F1: Notes | G1: Timestamp | H1: InputBy

Sheet SL_Income_Log
A1: ID | B1: MonthKey | C1: Type | D1: Amount | E1: Spender | F1: Description | G1: Timestamp | H1: InputBy

Sheet SL_Config
A1: key | B1: value
A2: discord_webhook_url | B2: https://discord.com/api/webhooks/1450509364107546636/kPJPDwRkoi90cz1lOqHhKii3rZ2mRc4ZYmfsXffNoPznLutEsphUTMqQDA_7IhUNxyGn
A3: h_discord_username | B3: hewhoremains_80685
A4: w_discord_username | B4: trang_54164
A5: timezone | B5: Europe/Berlin
A6: daily_summary_hour | B6: 21
A7: weekly_summary_day | B7: 0
A8: alert_threshold_warning | B8: 0.8
A9: alert_threshold_info | B9: 0.5
A10: gemini_api_key

Sheet SL_Patterns
A1: pattern | B1: category | C1: confidence | D1: source | E1: last_used
A2: rewe | B2: Groceries + Food | C2: high | D2: builtin | E2: 46007.515
A3: lidl | B3: Groceries + Food | C3: high | D3: builtin | E3: 46007.545
A4: edeka | B4: Groceries + Food | C4: high | D4: builtin
A5: aldi | B5: Groceries + Food | C5: high | D5: builtin
A6: penny | B6: Groceries + Food | C6: high | D6: builtin
A7: netto | B7: Groceries + Food | C7: high | D7: builtin
A8: kaufland | B8: Groceries + Food | C8: high | D8: builtin
A9: globus | B9: Groceries + Food | C9: high | D9: builtin
A10: lieferando | B10: Eat Out & Food delivery | C10: high | D10: builtin
A11: wolt | B11: Eat Out & Food delivery | C11: high | D11: builtin
A12: uber eats | B12: Eat Out & Food delivery | C12: high | D12: builtin
A13: kebab | B13: Eat Out & Food delivery | C13: high | D13: builtin
A14: döner | B14: Eat Out & Food delivery | C14: high | D14: builtin
A15: mcdonald | B15: Eat Out & Food delivery | C15: high | D15: builtin
... A62: axa | B62: Insurance | C62: high | D62: builtin

Sheet SL_Budget
A1: category | B1: Budget | C1: Month_Key | D1: Spent | E1: Remaining | F1: Percent
A2: Childcare | B2: 920 | C2: 2025-12 | D2: =SUMIFS(ShadowLedger!$D:$D,ShadowLedger!$G:$G,A2,ShadowLedger!$C:$C,">="&DATE(LEFT(SUBSTITUTE(C2,"'",""),4),MID(SUBSTITUTE(C2,"'",""),6,2),1),ShadowLedger!$C:$C,"<"&EOMONTH(DATE(LEFT(SUBSTITUTE(C2,"'",""),4),MID(SUBSTITUTE(C2,"'",""),6,2),1),0)+1) -> 913 | E2: =B2-D2 -> 7 | F2: =IF(B2>0,D2/B2,0) -> 0.9923913
A3: Family Support | B3: 700 | C3: 2025-12 | D3: =SUMIFS(ShadowLedger!$D:$D,ShadowLedger!$G:$G,A3,ShadowLedger!$C:$C,">="&DATE(LEFT(SUBSTITUTE(C3,"'",""),4),MID(SUBSTITUTE(C3,"'",""),6,2),1),ShadowLedger!$C:$C,"<"&EOMONTH(DATE(LEFT(SUBSTITUTE(C3,"'",""),4),MID(SUBSTITUTE(C3,"'",""),6,2),1),0)+1) -> 229.57 | E3: =B3-D3 -> 470.43 | F3: =IF(B3>0,D3/B3,0) -> 0.32795714
A4: Groceries + Food | B4: 500 | C4: 2025-12 | D4: =SUMIFS(ShadowLedger!$D:$D,ShadowLedger!$G:$G,A4,ShadowLedger!$C:$C,">="&DATE(LEFT(SUBSTITUTE(C4,"'",""),4),MID(SUBSTITUTE(C4,"'",""),6,2),1),ShadowLedger!$C:$C,"<"&EOMONTH(DATE(LEFT(SUBSTITUTE(C4,"'",""),4),MID(SUBSTITUTE(C4,"'",""),6,2),1),0)+1) -> 907.1 | E4: =B4-D4 -> -407.1 | F4: =IF(B4>0,D4/B4,0) -> 1.8142
A5: Utilities | B5: 500 | C5: 2025-12 | D5: =SUMIFS(ShadowLedger!$D:$D,ShadowLedger!$G:$G,A5,ShadowLedger!$C:$C,">="&DATE(LEFT(SUBSTITUTE(C5,"'",""),4),MID(SUBSTITUTE(C5,"'",""),6,2),1),ShadowLedger!$C:$C,"<"&EOMONTH(DATE(LEFT(SUBSTITUTE(C5,"'",""),4),MID(SUBSTITUTE(C5,"'",""),6,2),1),0)+1) -> 55 | E5: =B5-D5 -> 445 | F5: =IF(B5>0,D5/B5,0) -> 0.11
A6: Car | B6: 400 | C6: 2025-12 | D6: =SUMIFS(ShadowLedger!$D:$D,ShadowLedger!$G:$G,A6,ShadowLedger!$C:$C,">="&DATE(LEFT(SUBSTITUTE(C6,"'",""),4),MID(SUBSTITUTE(C6,"'",""),6,2),1),ShadowLedger!$C:$C,"<"&EOMONTH(DATE(LEFT(SUBSTITUTE(C6,"'",""),4),MID(SUBSTITUTE(C6,"'",""),6,2),1),0)+1) -> 882 | E6: =B6-D6 -> -482 | F6: =IF(B6>0,D6/B6,0) -> 2.205
A7: Shopping | B7: 200 | C7: 2025-12 | D7: =SUMIFS(ShadowLedger!$D:$D,ShadowLedger!$G:$G,A7,ShadowLedger!$C:$C,">="&DATE(LEFT(SUBSTITUTE(C7,"'",""),4),MID(SUBSTITUTE(C7,"'",""),6,2),1),ShadowLedger!$C:$C,"<"&EOMONTH(DATE(LEFT(SUBSTITUTE(C7,"'",""),4),MID(SUBSTITUTE(C7,"'",""),6,2),1),0)+1) -> 457.21 | E7: =B7-D7 -> -257.21 | F7: =IF(B7>0,D7/B7,0) -> 2.28605
A8: Travel & Leisure | B8: 150 | C8: 2025-12 | D8: =SUMIFS(ShadowLedger!$D:$D,ShadowLedger!$G:$G,A8,ShadowLedger!$C:$C,">="&DATE(LEFT(SUBSTITUTE(C8,"'",""),4),MID(SUBSTITUTE(C8,"'",""),6,2),1),ShadowLedger!$C:$C,"<"&EOMONTH(DATE(LEFT(SUBSTITUTE(C8,"'",""),4),MID(SUBSTITUTE(C8,"'",""),6,2),1),0)+1) -> 792.58 | E8: =B8-D8 -> -642.58 | F8: =IF(B8>0,D8/B8,0) -> 5.2838667
A9: Insurance | B9: 120 | C9: 2025-12 | D9: =SUMIFS(ShadowLedger!$D:$D,ShadowLedger!$G:$G,A9,ShadowLedger!$C:$C,">="&DATE(LEFT(SUBSTITUTE(C9,"'",""),4),MID(SUBSTITUTE(C9,"'",""),6,2),1),ShadowLedger!$C:$C,"<"&EOMONTH(DATE(LEFT(SUBSTITUTE(C9,"'",""),4),MID(SUBSTITUTE(C9,"'",""),6,2),1),0)+1) -> 0 | E9: =B9-D9 -> 120 | F9: =IF(B9>0,D9/B9,0) -> 0
A10: Eat Out & Food delivery | B10: 120 | C10: 2025-12 | D10: =SUMIFS(ShadowLedger!$D:$D,ShadowLedger!$G:$G,A10,ShadowLedger!$C:$C,">="&DATE(LEFT(SUBSTITUTE(C10,"'",""),4),MID(SUBSTITUTE(C10,"'",""),6,2),1),ShadowLedger!$C:$C,"<"&EOMONTH(DATE(LEFT(SUBSTITUTE(C10,"'",""),4),MID(SUBSTITUTE(C10,"'",""),6,2),1),0)+1) -> 160.5 | E10: =B10-D10 -> -40.5 | F10: =IF(B10>0,D10/B10,0) -> 1.3375
A11: Gifts | B11: 100 | C11: 2025-12 | D11: =SUMIFS(ShadowLedger!$D:$D,ShadowLedger!$G:$G,A11,ShadowLedger!$C:$C,">="&DATE(LEFT(SUBSTITUTE(C11,"'",""),4),MID(SUBSTITUTE(C11,"'",""),6,2),1),ShadowLedger!$C:$C,"<"&EOMONTH(DATE(LEFT(SUBSTITUTE(C11,"'",""),4),MID(SUBSTITUTE(C11,"'",""),6,2),1),0)+1) -> 524.45 | E11: =B11-D11 -> -424.45 | F11: =IF(B11>0,D11/B11,0) -> 5.2445
A12: Entertainment | B12: 100 | C12: 2025-12 | D12: =SUMIFS(ShadowLedger!$D:$D,ShadowLedger!$G:$G,A12,ShadowLedger!$C:$C,">="&DATE(LEFT(SUBSTITUTE(C12,"'",""),4),MID(SUBSTITUTE(C12,"'",""),6,2),1),ShadowLedger!$C:$C,"<"&EOMONTH(DATE(LEFT(SUBSTITUTE(C12,"'",""),4),MID(SUBSTITUTE(C12,"'",""),6,2),1),0)+1) -> 0 | E12: =B12-D12 -> 100 | F12: =IF(B12>0,D12/B12,0) -> 0
A13: Buffer | B13: 100 | C13: 2025-12 | D13: =SUMIFS(ShadowLedger!$D:$D,ShadowLedger!$G:$G,A13,ShadowLedger!$C:$C,">="&DATE(LEFT(SUBSTITUTE(C13,"'",""),4),MID(SUBSTITUTE(C13,"'",""),6,2),1),ShadowLedger!$C:$C,"<"&EOMONTH(DATE(LEFT(SUBSTITUTE(C13,"'",""),4),MID(SUBSTITUTE(C13,"'",""),6,2),1),0)+1) -> 67.37 | E13: =B13-D13 -> 32.63 | F13: =IF(B13>0,D13/B13,0) -> 0.6737
... A3486: Special IO | B3486: 0 | C3486: 2042-12 | D3486: =SUMIFS(ShadowLedger!$D:$D,ShadowLedger!$G:$G,A3486,ShadowLedger!$C:$C,">="&DATE(LEFT(SUBSTITUTE(C3486,"'",""),4),MID(SUBSTITUTE(C3486,"'",""),6,2),1),ShadowLedger!$C:$C,"<"&EOMONTH(DATE(LEFT(SUBSTITUTE(C3486,"'",""),4),MID(SUBSTITUTE(C3486,"'",""),6,2),1),0)+1) -> 0 | E3486: =B3486-D3486 -> 0 | F3486: =IF(B3486>0,D3486/B3486,0) -> 0

Sheet SL_Budget_Backup
A1: category | B1: monthly_budget | C1: current_spent | D1: remaining | E1: percent_used | F1: status
A2: Childcare | B2: 920 | C2: =SUMIFS(ShadowLedger!D:D,ShadowLedger!G:G,A2,ShadowLedger!O:O,TEXT(TODAY(),"YYYY-MM")) -> 913 | D2: =B2-C2 -> 7 | E2: =IF(B2>0,C2/B2,0) -> 0.9923913 | F2: =IF(E2>=1,"🔴 OVER",IF(E2>=0.8,"🟠 WARNING",IF(E2>=0.5,"🟡 INFO","🟢 OK"))) -> 🟠 WARNING
A3: Family Support | B3: 700 | C3: =SUMIFS(ShadowLedger!D:D,ShadowLedger!G:G,A3,ShadowLedger!O:O,TEXT(TODAY(),"YYYY-MM")) -> 229.57 | D3: =B3-C3 -> 470.43 | E3: =IF(B3>0,C3/B3,0) -> 0.32795714 | F3: =IF(E3>=1,"🔴 OVER",IF(E3>=0.8,"🟠 WARNING",IF(E3>=0.5,"🟡 INFO","🟢 OK"))) -> 🟢 OK
A4: Groceries + Food | B4: 500 | C4: =SUMIFS(ShadowLedger!D:D,ShadowLedger!G:G,A4,ShadowLedger!O:O,TEXT(TODAY(),"YYYY-MM")) -> 907.1 | D4: =B4-C4 -> -407.1 | E4: =IF(B4>0,C4/B4,0) -> 1.8142 | F4: =IF(E4>=1,"🔴 OVER",IF(E4>=0.8,"🟠 WARNING",IF(E4>=0.5,"🟡 INFO","🟢 OK"))) -> 🔴 OVER
A5: Utilities | B5: 500 | C5: =SUMIFS(ShadowLedger!D:D,ShadowLedger!G:G,A5,ShadowLedger!O:O,TEXT(TODAY(),"YYYY-MM")) -> 55 | D5: =B5-C5 -> 445 | E5: =IF(B5>0,C5/B5,0) -> 0.11 | F5: =IF(E5>=1,"🔴 OVER",IF(E5>=0.8,"🟠 WARNING",IF(E5>=0.5,"🟡 INFO","🟢 OK"))) -> 🟢 OK
A6: Car | B6: 400 | C6: =SUMIFS(ShadowLedger!D:D,ShadowLedger!G:G,A6,ShadowLedger!O:O,TEXT(TODAY(),"YYYY-MM")) -> 882 | D6: =B6-C6 -> -482 | E6: =IF(B6>0,C6/B6,0) -> 2.205 | F6: =IF(E6>=1,"🔴 OVER",IF(E6>=0.8,"🟠 WARNING",IF(E6>=0.5,"🟡 INFO","🟢 OK"))) -> 🔴 OVER
A7: Shopping | B7: 200 | C7: =SUMIFS(ShadowLedger!D:D,ShadowLedger!G:G,A7,ShadowLedger!O:O,TEXT(TODAY(),"YYYY-MM")) -> 457.21 | D7: =B7-C7 -> -257.21 | E7: =IF(B7>0,C7/B7,0) -> 2.28605 | F7: =IF(E7>=1,"🔴 OVER",IF(E7>=0.8,"🟠 WARNING",IF(E7>=0.5,"🟡 INFO","🟢 OK"))) -> 🔴 OVER
A8: Travel & Leisure | B8: 150 | C8: =SUMIFS(ShadowLedger!D:D,ShadowLedger!G:G,A8,ShadowLedger!O:O,TEXT(TODAY(),"YYYY-MM")) -> 792.58 | D8: =B8-C8 -> -642.58 | E8: =IF(B8>0,C8/B8,0) -> 5.2838667 | F8: =IF(E8>=1,"🔴 OVER",IF(E8>=0.8,"🟠 WARNING",IF(E8>=0.5,"🟡 INFO","🟢 OK"))) -> 🔴 OVER
A9: Insurance | B9: 120 | C9: =SUMIFS(ShadowLedger!D:D,ShadowLedger!G:G,A9,ShadowLedger!O:O,TEXT(TODAY(),"YYYY-MM")) -> 0 | D9: =B9-C9 -> 120 | E9: =IF(B9>0,C9/B9,0) -> 0 | F9: =IF(E9>=1,"🔴 OVER",IF(E9>=0.8,"🟠 WARNING",IF(E9>=0.5,"🟡 INFO","🟢 OK"))) -> 🟢 OK
A10: Eat Out & Food delivery | B10: 120 | C10: =SUMIFS(ShadowLedger!D:D,ShadowLedger!G:G,A10,ShadowLedger!O:O,TEXT(TODAY(),"YYYY-MM")) -> 160.5 | D10: =B10-C10 -> -40.5 | E10: =IF(B10>0,C10/B10,0) -> 1.3375 | F10: =IF(E10>=1,"🔴 OVER",IF(E10>=0.8,"🟠 WARNING",IF(E10>=0.5,"🟡 INFO","🟢 OK"))) -> 🔴 OVER
A11: Gifts | B11: 100 | C11: =SUMIFS(ShadowLedger!D:D,ShadowLedger!G:G,A11,ShadowLedger!O:O,TEXT(TODAY(),"YYYY-MM")) -> 524.45 | D11: =B11-C11 -> -424.45 | E11: =IF(B11>0,C11/B11,0) -> 5.2445 | F11: =IF(E11>=1,"🔴 OVER",IF(E11>=0.8,"🟠 WARNING",IF(E11>=0.5,"🟡 INFO","🟢 OK"))) -> 🔴 OVER
A12: Entertainment | B12: 100 | C12: =SUMIFS(ShadowLedger!D:D,ShadowLedger!G:G,A12,ShadowLedger!O:O,TEXT(TODAY(),"YYYY-MM")) -> 0 | D12: =B12-C12 -> 100 | E12: =IF(B12>0,C12/B12,0) -> 0 | F12: =IF(E12>=1,"🔴 OVER",IF(E12>=0.8,"🟠 WARNING",IF(E12>=0.5,"🟡 INFO","🟢 OK"))) -> 🟢 OK
A13: Buffer | B13: 100 | C13: =SUMIFS(ShadowLedger!D:D,ShadowLedger!G:G,A13,ShadowLedger!O:O,TEXT(TODAY(),"YYYY-MM")) -> 67.37 | D13: =B13-C13 -> 32.63 | E13: =IF(B13>0,C13/B13,0) -> 0.6737 | F13: =IF(E13>=1,"🔴 OVER",IF(E13>=0.8,"🟠 WARNING",IF(E13>=0.5,"🟡 INFO","🟢 OK"))) -> 🟡 INFO
... A18: Special IO | B18: 0 | C18: =SUMIFS(ShadowLedger!D:D,ShadowLedger!G:G,A18,ShadowLedger!O:O,TEXT(TODAY(),"YYYY-MM")) -> 2210.76 | D18: =B18-C18 -> -2210.76 | E18: =IF(B18>0,C18/B18,0) -> 0 | F18: =IF(E18>=1,"🔴 OVER",IF(E18>=0.8,"🟠 WARNING",IF(E18>=0.5,"🟡 INFO","🟢 OK"))) -> 🟢 OK
B19: =SUM(B2:B18) -> 4110 | C19: =SUM(C2:C18) -> 8123.14 | D19: =SUM(D2:D18) -> -4013.14 | E19: =IF(B19>0,C19/B19,0) -> 1.9764331 | F19: =IF(E19>=1,"🔴 OVER",IF(E19>=0.8,"🟠 WARNING",IF(E19>=0.5,"🟡 INFO","🟢 OK"))) -> 🔴 OVER

Sheet ShadowLedger
A1: txn_id | B1: timestamp | C1: txn_date | D1: amount | E1: merchant | F1: description | G1: category | H1: spender | I1: inputter | J1: input_method | K1: categorization | L1: reviewed | M1: review_date | N1: raw_input | O1: month_key
A2: SL-20251218-155837-073 | B2: 46009.666 | C2: 46009.666 | D2: 10 | E2: cheese in nancy | G2: Travel & Leisure | H2: H | I2: H | J2: Discord | K2: ai | L2: FALSE | N2: 10e cheese in nancy | O2: 2025-12
A3: SL-20251218-155922-024 | B3: 46009.666 | C3: 46009.666 | D3: 122 | E3: Auchan in nancy groceries | G3: Travel & Leisure | H3: H | I3: H | J3: Discord | K3: ai | L3: FALSE | N3: Auchan 122e in nancy groceries | O3: 2025-12
A4: SL-20251218-160010-992 | B4: 46009.667 | C4: 46009.667 | D4: 4.8 | E4: Toll road nancy | G4: Travel & Leisure | H4: H | I4: H | J4: Discord | K4: ai | L4: FALSE | N4: Toll road nancy 4,8e | O4: 2025-12
A5: SL-20251218-160055-896 | B5: 46009.667 | C5: 46009.667 | D5: 5.4 | E5: Bread croissant nancy | G5: Travel & Leisure | H5: H | I5: H | J5: Discord | K5: ai | L5: FALSE | N5: Bread croissant 5,4e nancy | O5: 2025-12
A6: SL-20251218-162337-739 | B6: 46009.683 | C6: 46009.683 | D6: 13.1 | E6: Cakes in nancy | G6: Travel & Leisure | H6: H | I6: H | J6: Discord | K6: ai | L6: FALSE | N6: 13,10 category: eat-out, item: cakes | O6: 2025-12
A7: SL-20251218-205454-201 | B7: 46009.871 | C7: 46009.871 | D7: 24 | E7: Carrefour, category: groceries | G7: Travel & Leisure | H7: W | I7: H | J7: Discord | K7: user | L7: TRUE | M7: 46009.871 | N7: Trang 24e carrefour, category: groceries | O7: 2025-12
A8: SL-20251218-205529-115 | B8: 46009.872 | C8: 46009.872 | D8: 14 | E8: mcdonalds eat-out | G8: Travel & Leisure | H8: W | I8: H | J8: Discord | K8: ai | L8: FALSE | N8: Trang 14e mcdonalds eat-out | O8: 2025-12
A9: SL-20251219-195059-277 | B9: 46010.827 | C9: 46010.827 | D9: 95.28 | E9: category: travel, description: groceries and gift and food, merchant: nancy | G9: Travel & Leisure | H9: H | I9: H | J9: Discord | K9: ai | L9: FALSE | N9: 95,28e category: travel, description: groceries and gift and food, merchant: nancy | O9: 2025-12
A10: SL-20251221-163635-368 | B10: 46012.692 | C10: 46011.5 | D10: 225.8 | E10: category: travel, description: nancy | G10: Travel & Leisure | H10: H | I10: H | J10: Discord | K10: ai | L10: FALSE | N10: Yesterday 225,8 category: travel, description: nancy | O10: 2025-12
A11: SL-20251221-163704-779 | B11: 46012.692 | C11: 46012.692 | D11: 10.4 | E11: category: travel, description: nancy | G11: Travel & Leisure | H11: H | I11: H | J11: Discord | K11: ai | L11: FALSE | N11: 10,4 category: travel, description: nancy | O11: 2025-12
A12: SL-20251222-124059-687 | B12: 46013.528 | C12: 46013.528 | D12: 158 | E12: mua rofu , category: gift | G12: Gifts | H12: W | I12: W | J12: Discord | K12: ai | L12: FALSE | N12: Em mua rofu 158e, category: gift | O12: 2025-12
A13: SL-20251222-124149-164 | B13: 46013.529 | C13: 46013.529 | D13: 89 | E13: mua dehner , category: | G13: Home improvement | H13: W | I13: W | J13: Discord | K13: user | L13: TRUE | M13: 46013.529 | N13: Em mua dehner 89e, category: home improvement | O13: 2025-12
A14: SL-20251222-124245-908 | B14: 46013.53 | C14: 46013.53 | D14: 19.5 | E14: lidl | G14: Groceries + Food | H14: W | I14: W | J14: Discord | K14: ai | L14: FALSE | N14: lidl 19,5e | O14: 2025-12
A15: SL-20251222-165718-674 | B15: 46013.706 | C15: 46013.706 | D15: 14 | E15: Thuoc so mui AK | G15: Health & beauty | H15: H | I15: H | J15: Discord | K15: ai | L15: FALSE | N15: Thuoc so mui AK 14e | O15: 2025-12
A16: SL-20251222-224155-982 | B16: 46013.946 | C16: 46013.946 | D16: 22 | E16: Google subscription | G16: Business & Subscription | H16: H | I16: H | J16: Discord | K16: ai | L16: FALSE | N16: Google subscription 22e | O16: 2025-12
A17: SL-20251222-224202-002 | B17: 46013.946 | C17: 46013.946 | D17: 10 | E17: Apple subscription | G17: Business & Subscription | H17: H | I17: H | J17: Discord | K17: ai | L17: FALSE | N17: Apple subscription 10e | O17: 2025-12
A18: SL-20251223-072753-126 | B18: 46014.311 | C18: 46006.5 | D18: 913 | E18: Postillion | G18: Childcare | H18: H | I18: H | J18: Discord | K18: user | L18: TRUE | M18: 46014.311 | N18: 15.12 childcare 913€ | O18: 2025-12
A19: SL-20251223-073034-927 | B19: 46014.313 | C19: 45992.5 | D19: 327.95 | E19: Donation Phú Yên | F19: 10tr | G19: Donation | H19: H | I19: H | J19: Discord | K19: user | L19: TRUE | M19: 46014.313 | N19: 327,95 donation 01.12 | O19: 2025-12
A20: SL-20251223-073036-542 | B20: 46014.313 | C20: 45992.5 | D20: 229.57 | E20: Dú | F20: 7tr | G20: Family Support | H20: H | I20: H | J20: Discord | K20: user | L20: TRUE | M20: 46014.313 | N20: 229,57 family support 01.12 | O20: 2025-12
A21: SL-20251223-075424-422 | B21: 46014.329 | C21: 45992.5 | D21: 166.41 | E21: chó mèo vn | G21: Donation | H21: W | I21: H | J21: Discord | K21: user | L21: TRUE | M21: 46014.329 | N21: trang 01.12 donation chó mèo vn 166,41€ | O21: 2025-12
A22: SL-20251223-075427-802 | B22: 46014.329 | C22: 45992.5 | D22: 5 | E22: cafe mannheim | G22: Eat Out & Food delivery | H22: W | I22: H | J22: Discord | K22: ai | L22: FALSE | N22: trang 01.12 cafe mannheim 5€ | O22: 2025-12
A23: SL-20251223-075428-173 | B23: 46014.329 | C23: 45994.5 | D23: 12 | E23: disney+ | G23: Business & Subscription | H23: W | I23: H | J23: Discord | K23: user | L23: TRUE | M23: 46014.329 | N23: trang 03.12 disney+ business & subscription 12€ | O23: 2025-12
A24: SL-20251223-075430-713 | B24: 46014.33 | C24: 45996.5 | D24: 13 | E24: bread mannheim | G24: Eat Out & Food delivery | H24: W | I24: H | J24: Discord | K24: ai | L24: FALSE | N24: trang 05.12 bread mannheim 13€ | O24: 2025-12
A25: SL-20251223-075432-200 | B25: 46014.33 | C25: 45997.5 | D25: 3 | E25: cafe karlsruhe | G25: Eat Out & Food delivery | H25: W | I25: H | J25: Discord | K25: ai | L25: FALSE | N25: trang 06.12 cafe karlsruhe 3€ | O25: 2025-12
A26: SL-20251223-075433-591 | B26: 46014.33 | C26: 46006.5 | D26: 55 | E26: internet vodafone | G26: Utilities | H26: W | I26: H | J26: Discord | K26: user | L26: TRUE | M26: 46014.33 | N26: trang 15.12 utilities internet vodafone 55€ | O26: 2025-12
A27: SL-20251223-075434-765 | B27: 46014.33 | C27: 46007.5 | D27: 450 | E27: driving lessons | G27: Car | H27: W | I27: H | J27: Discord | K27: ai | L27: FALSE | N27: trang 16.12 driving lessons 450€ | O27: 2025-12
A28: SL-20251223-075435-821 | B28: 46014.33 | C28: 46007.5 | D28: 48.5 | E28: galeria mua quà maija | G28: Gifts | H28: W | I28: H | J28: Discord | K28: user | L28: TRUE | M28: 46014.33 | N28: trang 16.12 gifts galeria mua quà maija 48,5€ | O28: 2025-12
A29: SL-20251223-075437-175 | B29: 46014.33 | C29: 46008.5 | D29: 56 | E29: zalando áo tuyết AK | G29: Shopping | H29: W | I29: H | J29: Discord | K29: user | L29: TRUE | M29: 46014.33 | N29: trang 17.12 zalando shopping áo tuyết AK 56€ | O29: 2025-12
A30: SL-20251223-075438-869 | B30: 46014.33 | C30: 45992.5 | D30: 101.83 | E30: kaufland | G30: Groceries + Food | H30: W | I30: H | J30: Discord | K30: ai | L30: FALSE | N30: trang 01.12 kaufland 101,83€ | O30: 2025-12
A31: SL-20251223-075439-754 | B31: 46014.33 | C31: 45993.5 | D31: 47 | E31: rewe | G31: Groceries + Food | H31: W | I31: H | J31: Discord | K31: ai | L31: FALSE | N31: trang 02.12 rewe 47€ | O31: 2025-12
A32: SL-20251223-075441-692 | B32: 46014.33 | C32: 45993.5 | D32: 2137.76 | E32: flight ticket VN | G32: Special IO | H32: W | I32: H | J32: Discord | K32: user | L32: TRUE | M32: 46014.33 | N32: trang 02.12 special IO flight ticket VN 2137,76€ | O32: 2025-12
A33: SL-20251223-075443-091 | B33: 46014.33 | C33: 45993.5 | D33: 73 | E33: hotel singapore | G33: Special IO | H33: W | I33: H | J33: Discord | K33: user | L33: TRUE | M33: 46014.33 | N33: trang 02.12 special IO hotel singapore 73€ | O33: 2025-12
A34: SL-20251223-075444-768 | B34: 46014.33 | C34: 45996.5 | D34: 206 | E34: globus | G34: Groceries + Food | H34: W | I34: H | J34: Discord | K34: ai | L34: FALSE | N34: trang 05.12 globus 206€ | O34: 2025-12
A35: SL-20251223-075446-089 | B35: 46014.33 | C35: 45997.5 | D35: 15 | E35: karsruhe cafe | G35: Buffer | H35: W | I35: H | J35: Discord | K35: ai | L35: FALSE | N35: trang 06.12 karsruhe cafe 15€ | O35: 2025-12
A36: SL-20251223-075446-017 | B36: 46014.33 | C36: 45999.5 | D36: 40.7 | E36: vé tàu bé phúc | G36: Travel & Leisure | H36: W | I36: H | J36: Discord | K36: user | L36: TRUE | M36: 46014.33 | N36: trang 08.12 travel & leisure vé tàu bé phúc 40,7€ | O36: 2025-12
A37: SL-20251223-075447-667 | B37: 46014.33 | C37: 46002.5 | D37: 60 | E37: penny food | G37: Groceries + Food | H37: W | I37: H | J37: Discord | K37: ai | L37: FALSE | N37: trang 11.12 penny food 60€ | O37: 2025-12
A38: SL-20251223-075448-016 | B38: 46014.33 | C38: 46006.5 | D38: 12.36 | E38: lidl | G38: Groceries + Food | H38: W | I38: H | J38: Discord | K38: ai | L38: FALSE | N38: trang 15.12 lidl 12,36€ | O38: 2025-12
A39: SL-20251223-075449-043 | B39: 46014.33 | C39: 46007.5 | D39: 142.25 | E39: zalando bé đức + biuti | G39: Gifts | H39: W | I39: H | J39: Discord | K39: user | L39: TRUE | M39: 46014.33 | N39: trang 16.12 gifts zalando bé đức + biuti 142,25€ | O39: 2025-12
A40: SL-20251223-075637-500 | B40: 46014.331 | C40: 45992.5 | D40: 392 | E40: polestar | G40: Car | H40: H | I40: H | J40: Discord | K40: user | L40: TRUE | M40: 46014.331 | N40: car polestar 392€ 01.12 | O40: 2025-12
...

Sheet RSU_Schedule
A1: Month | B1: Year | C1: Date | D1: H_Backlog_Shares | E1: H_NewGrant_Shares | F1: H_Total_Shares | G1: H_Gross_EUR | H1: H_Net_EUR | I1: W_Backlog_Shares | J1: W_NewGrant_Shares | K1: W_Total_Shares | L1: W_Gross_EUR | M1: W_Net_EUR | N1: Combined_Net_EUR
A2: 1 | B2: 2026 | C2: 01/2026 | D2: 0 | E2: 0 | F2: 0 | G2: 0 | H2: 0 | I2: 0 | J2: 0 | K2: 0 | L2: 0 | M2: 0 | N2: 0
A3: 2 | B3: 2026 | C3: 02/2026 | D3: 0 | E3: 0 | F3: 0 | G3: 0 | H3: 0 | I3: 0 | J3: 0 | K3: 0 | L3: 0 | M3: 0 | N3: 0
A4: 3 | B4: 2026 | C4: 03/2026 | D4: 40.94 | E4: 0 | F4: 40.94 | G4: 8597.4 | H4: 4788.75 | I4: 20.47 | J4: 0 | K4: 20.47 | L4: 4298.7 | M4: 2394.38 | N4: 7183.13
A5: 4 | B5: 2026 | C5: 04/2026 | D5: 0 | E5: 0 | F5: 0 | G5: 0 | H5: 0 | I5: 0 | J5: 0 | K5: 0 | L5: 0 | M5: 0 | N5: 0
A6: 5 | B6: 2026 | C6: 05/2026 | D6: 0 | E6: 0 | F6: 0 | G6: 0 | H6: 0 | I6: 0 | J6: 0 | K6: 0 | L6: 0 | M6: 0 | N6: 0
A7: 6 | B7: 2026 | C7: 06/2026 | D7: 25.91 | E7: 0 | F7: 25.91 | G7: 5441.1 | H7: 3030.69 | I7: 12.955 | J7: 0 | K7: 12.955 | L7: 2720.55 | M7: 1515.35 | N7: 4546.04
A8: 7 | B8: 2026 | C8: 07/2026 | D8: 0 | E8: 0 | F8: 0 | G8: 0 | H8: 0 | I8: 0 | J8: 0 | K8: 0 | L8: 0 | M8: 0 | N8: 0
A9: 8 | B9: 2026 | C9: 08/2026 | D9: 0 | E9: 0 | F9: 0 | G9: 0 | H9: 0 | I9: 0 | J9: 0 | K9: 0 | L9: 0 | M9: 0 | N9: 0
A10: 9 | B10: 2026 | C10: 09/2026 | D10: 25.91 | E10: 7.9365 | F10: 33.8465 | G10: 7107.76 | H10: 3959.02 | I10: 12.955 | J10: 3.9683 | K10: 16.9233 | L10: 3553.89 | M10: 1979.52 | N10: 5938.54
A11: 10 | B11: 2026 | C11: 10/2026 | D11: 0 | E11: 0 | F11: 0 | G11: 0 | H11: 0 | I11: 0 | J11: 0 | K11: 0 | L11: 0 | M11: 0 | N11: 0
A12: 11 | B12: 2026 | C12: 11/2026 | D12: 0 | E12: 0 | F12: 0 | G12: 0 | H12: 0 | I12: 0 | J12: 0 | K12: 0 | L12: 0 | M12: 0 | N12: 0
A13: 12 | B13: 2026 | C13: 12/2026 | D13: 25.91 | E13: 7.9365 | F13: 33.8465 | G13: 7107.76 | H13: 3959.02 | I13: 12.955 | J13: 3.9683 | K13: 16.9233 | L13: 3553.89 | M13: 1979.52 | N13: 5938.54
... A205: 12 | B205: 2042 | C205: 12/2042 | D205: 0 | E205: 23.8095 | F205: 23.8095 | G205: 4999.99 | H205: 2784.99 | I205: 0 | J205: 11.9048 | K205: 11.9048 | L205: 2500.01 | M205: 1392.51 | N205: 4177.5

Sheet Salary_Schedule
A1: Year | B1: Month | C1: H_Salary_Modifier | D1: W_Salary_Modifier | E1: H_Fixed_Monthly | F1: H_Bonus | G1: W_Fixed_Monthly | H1: W_Bonus | I1: Notes
A2: 2026 | B2: 1 | C2: 0 | D2: 0 | E2: =7366.42*(1+C2) -> 7366.42 | F2: 0 | G2: =6195.67*(1+D2) -> 6195.67 | H2: 0
A3: 2026 | B3: 2 | C3: 0 | D3: 0 | E3: =7366.42*(1+C3) -> 7366.42 | F3: 0 | G3: =6195.67*(1+D3) -> 6195.67 | H3: 0
A4: 2026 | B4: 3 | C4: 0 | D4: 0 | E4: =7366.42*(1+C4) -> 7366.42 | F4: 0 | G4: =6195.67*(1+D4) -> 6195.67 | H4: 0
A5: 2026 | B5: 4 | C5: 0 | D5: 0 | E5: =7366.42*(1+C5) -> 7366.42 | F5: =9821*(1+C5) -> 9821 | G5: =6195.67*(1+D5) -> 6195.67 | H5: =8261*(1+D5) -> 8261
A6: 2026 | B6: 5 | C6: 0 | D6: 0 | E6: =7366.42*(1+C6) -> 7366.42 | F6: 0 | G6: =6195.67*(1+D6) -> 6195.67 | H6: 0
A7: 2026 | B7: 6 | C7: 0 | D7: 0 | E7: =7366.42*(1+C7) -> 7366.42 | F7: 0 | G7: =6195.67*(1+D7) -> 6195.67 | H7: 0
A8: 2026 | B8: 7 | C8: 0 | D8: 0 | E8: =7366.42*(1+C8) -> 7366.42 | F8: 0 | G8: =6195.67*(1+D8) -> 6195.67 | H8: 0
A9: 2026 | B9: 8 | C9: 0 | D9: 0 | E9: =7366.42*(1+C9) -> 7366.42 | F9: 0 | G9: =6195.67*(1+D9) -> 6195.67 | H9: 0
A10: 2026 | B10: 9 | C10: 0 | D10: 0 | E10: =7366.42*(1+C10) -> 7366.42 | F10: 0 | G10: =6195.67*(1+D10) -> 6195.67 | H10: 0
A11: 2026 | B11: 10 | C11: 0 | D11: 0 | E11: =7366.42*(1+C11) -> 7366.42 | F11: 0 | G11: =6195.67*(1+D11) -> 6195.67 | H11: 0
A12: 2026 | B12: 11 | C12: 0 | D12: 0 | E12: =7366.42*(1+C12) -> 7366.42 | F12: 0 | G12: =6195.67*(1+D12) -> 6195.67 | H12: 0
A13: 2026 | B13: 12 | C13: 0 | D13: 0 | E13: =7366.42*(1+C13) -> 7366.42 | F13: 0 | G13: =6195.67*(1+D13) -> 6195.67 | H13: 0
A14: 2027 | B14: 1 | C14: 0 | D14: 0 | E14: =7734.74*(1+C14) -> 7734.74 | F14: 0 | G14: =6412.51*(1+D14) -> 6412.51 | H14: 0
A15: 2027 | B15: 2 | C15: 0 | D15: 0 | E15: =7734.74*(1+C15) -> 7734.74 | F15: 0 | G15: =6412.51*(1+D15) -> 6412.51 | H15: 0
A16: 2027 | B16: 3 | C16: 0 | D16: 0 | E16: =7734.74*(1+C16) -> 7734.74 | F16: 0 | G16: =6412.51*(1+D16) -> 6412.51 | H16: 0
A17: 2027 | B17: 4 | C17: 0 | D17: 0 | E17: =7734.74*(1+C17) -> 7734.74 | F17: =10312.05*(1+C17) -> 10312.05 | G17: =6412.51*(1+D17) -> 6412.51 | H17: =8550.14*(1+D17) -> 8550.14
A18: 2027 | B18: 5 | C18: 0 | D18: 0 | E18: =7734.74*(1+C18) -> 7734.74 | F18: 0 | G18: =6412.51*(1+D18) -> 6412.51 | H18: 0
A19: 2027 | B19: 6 | C19: 0 | D19: 0 | E19: =7734.74*(1+C19) -> 7734.74 | F19: 0 | G19: =6412.51*(1+D19) -> 6412.51 | H19: 0
A20: 2027 | B20: 7 | C20: 0 | D20: 0 | E20: =7734.74*(1+C20) -> 7734.74 | F20: 0 | G20: =6412.51*(1+D20) -> 6412.51 | H20: 0
A21: 2027 | B21: 8 | C21: 0 | D21: 0 | E21: =7734.74*(1+C21) -> 7734.74 | F21: 0 | G21: =6412.51*(1+D21) -> 6412.51 | H21: 0
A22: 2027 | B22: 9 | C22: 0 | D22: 0 | E22: =7734.74*(1+C22) -> 7734.74 | F22: 0 | G22: =6412.51*(1+D22) -> 6412.51 | H22: 0
A23: 2027 | B23: 10 | C23: 0 | D23: 0 | E23: =7734.74*(1+C23) -> 7734.74 | F23: 0 | G23: =6412.51*(1+D23) -> 6412.51 | H23: 0
A24: 2027 | B24: 11 | C24: 0 | D24: 0 | E24: =7734.74*(1+C24) -> 7734.74 | F24: 0 | G24: =6412.51*(1+D24) -> 6412.51 | H24: 0
A25: 2027 | B25: 12 | C25: 0 | D25: 0 | E25: =7734.74*(1+C25) -> 7734.74 | F25: 0 | G25: =6412.51*(1+D25) -> 6412.51 | H25: 0
A26: 2028 | B26: 1 | C26: 0 | D26: 0 | E26: =8121.47*(1+C26) -> 8121.47 | F26: 0 | G26: =6636.95*(1+D26) -> 6636.95 | H26: 0
A27: 2028 | B27: 2 | C27: 0 | D27: 0 | E27: =8121.47*(1+C27) -> 8121.47 | F27: 0 | G27: =6636.95*(1+D27) -> 6636.95 | H27: 0
A28: 2028 | B28: 3 | C28: 0 | D28: 0 | E28: =8121.47*(1+C28) -> 8121.47 | F28: 0 | G28: =6636.95*(1+D28) -> 6636.95 | H28: 0
A29: 2028 | B29: 4 | C29: 0 | D29: 0 | E29: =8121.47*(1+C29) -> 8121.47 | F29: =10827.65*(1+C29) -> 10827.65 | G29: =6636.95*(1+D29) -> 6636.95 | H29: =8849.39*(1+D29) -> 8849.39
A30: 2028 | B30: 5 | C30: 0 | D30: 0 | E30: =8121.47*(1+C30) -> 8121.47 | F30: 0 | G30: =6636.95*(1+D30) -> 6636.95 | H30: 0
A31: 2028 | B31: 6 | C31: 0 | D31: 0 | E31: =8121.47*(1+C31) -> 8121.47 | F31: 0 | G31: =6636.95*(1+D31) -> 6636.95 | H31: 0
A32: 2028 | B32: 7 | C32: 0 | D32: 0 | E32: =8121.47*(1+C32) -> 8121.47 | F32: 0 | G32: =6636.95*(1+D32) -> 6636.95 | H32: 0
A33: 2028 | B33: 8 | C33: 0 | D33: 0 | E33: =8121.47*(1+C33) -> 8121.47 | F33: 0 | G33: =6636.95*(1+D33) -> 6636.95 | H33: 0
A34: 2028 | B34: 9 | C34: 0 | D34: 0 | E34: =8121.47*(1+C34) -> 8121.47 | F34: 0 | G34: =6636.95*(1+D34) -> 6636.95 | H34: 0
A35: 2028 | B35: 10 | C35: 0 | D35: 0 | E35: =8121.47*(1+C35) -> 8121.47 | F35: 0 | G35: =6636.95*(1+D35) -> 6636.95 | H35: 0
A36: 2028 | B36: 11 | C36: 0 | D36: 0 | E36: =8121.47*(1+C36) -> 8121.47 | F36: 0 | G36: =6636.95*(1+D36) -> 6636.95 | H36: 0
A37: 2028 | B37: 12 | C37: 0 | D37: 0 | E37: =8121.47*(1+C37) -> 8121.47 | F37: 0 | G37: =6636.95*(1+D37) -> 6636.95 | H37: 0
A38: 2029 | B38: 1 | C38: 0 | D38: 0 | E38: =8527.55*(1+C38) -> 8527.55 | F38: 0 | G38: =6869.25*(1+D38) -> 6869.25 | H38: 0
A39: 2029 | B39: 2 | C39: 0 | D39: 0 | E39: =8527.55*(1+C39) -> 8527.55 | F39: 0 | G39: =6869.25*(1+D39) -> 6869.25 | H39: 0
A40: 2029 | B40: 3 | C40: 0 | D40: 0 | E40: =8527.55*(1+C40) -> 8527.55 | F40: 0 | G40: =6869.25*(1+D40) -> 6869.25 | H40: 0
...

Sheet Debt_Register
A1: Debt_Name | B1: Owner | C1: Starting_Balance | D1: APR | E1: Min_Payment | F1: Payment_Type | G1: End_Date | H1: Attack_Priority
A2: TF Credit Card | B2: H | C2: 9200 | D2: 0.22 | E2: 300 | F2: Attack | G2: ASAP | H2: 1
A3: DB Overdraft | B3: H | C3: 2000 | D3: 0.13 | E3: 0 | F3: Attack | G3: Plan | H3: 2
A4: Revolut Loan | B4: H | C4: 12350 | D4: 0.0595 | E4: 650 | F4: Fixed | G4: Aug 2027
A5: C3 Family Loan | B5: H | C5: 10000 | D5: 0 | E5: 290 | F5: Fixed | G5: ~2028
A6: Scalable Credit | B6: H | C6: 5500 | D6: 0.033 | E6: 0 | F6: Low | G6: -
A7: Klarna | B7: W | C7: 2000 | D7: 0.14 | E7: 200 | F7: Attack | G7: Plan | H7: 3
A8: Nordea Card | B8: W | C8: 2000 | D8: 0.13 | E8: 100 | F8: Attack | G8: Plan | H8: 4
A9: Aktia Card | B9: W | C9: 440 | D9: 0.13 | E9: 30 | F9: Attack | G9: Plan | H9: 5
A10: Student Loan | B10: W | C10: 11000 | D10: 0.032 | E10: 200 | F10: Fixed | G10: ~2030
A11: IKEA Card | B11: W | C11: 2500 | D11: 0 | E11: 132 | F11: Fixed | G11: Jul 2027
A12: N26 Overdraft | B12: W | C12: 360 | D12: 0 | E12: 90 | F12: Fixed | G12: Apr 2026
A13: SAP Loan | B13: H+W | C13: 52500 | D13: 0 | E13: 583.33 | F13: Fixed | G13: Jun 2033
A14: AK Payback (Son) | B14: H+W | C14: 5000 | D14: 0 | E14: 0 | F14: Future | G14: TBD
A15: SUMMARY
A16: Total High-APR (>10%) | B16: =SUMIF(D2:D12,">0.1",C2:C12) -> 15640
A17: Total Fixed Payment | B17: =SUMIF(F2:F12,"Fixed",C2:C12) -> 36210
A18: Total Low Priority | B18: =SUMIF(F2:F12,"Low",C2:C12) -> 5500
A19: Monthly Minimums | B19: =SUM(E2:E12) -> 1992
A20: TOTAL DEBT | B20: =SUM(C2:C13) -> 109850

Sheet Monthly_Model_v4
A1: Month | B1: Year | C1: Date | D1: Income_From | E1: Month_Type | F1: H_Gross_Salary | G1: H_TA_Ded | H1: H_OWNSAP_Ded | I1: H_Gross_Bonus | J1: H_Bonus_TA | K1: H_Taxable | L1: H_Net_Salary | M1: H_RSU_Net | N1: W_Gross_Salary | O1: W_TA_Ded | P1: W_OWNSAP_Ded | Q1: W_Gross_Bonus | R1: W_Bonus_TA | S1: W_Taxable | T1: W_Net_Salary | U1: W_RSU_Net | V1: H_OWNSAP_Val | W1: W_OWNSAP_Val | X1: OWNSAP_Total | Y1: H_SAP_TaxedAdv | Z1: H_SAPLoan_Pmt | AA1: H_SAPLoan_Bal | AB1: W_SAP_TaxedAdv | AC1: W_SAPLoan_Pmt | AD1: W_SAPLoan_Bal | AE1: SAP_Loan_Pmt | AF1: SAP_Loan_Bal | AG1: YT_Gross | AH1: YT_Tax_Res | AI1: YT_Net | AJ1: Other_Fam_Net_Inc | AK1: CMP_Carry | AL1: CMP_Inflow | AM1: CMP_Available | AN1: CMP_End | AO1: Mort_Begin | AP1: Mort_Pmt | AQ1: Mort_Int | AR1: Mort_Princ | AS1: Sondertilg | AT1: Mort_End | AU1: D_TF_Pmt | AV1: D_TF_Bal | AW1: D_Klarna_Pmt | AX1: D_Klarna_Bal | AY1: D_Nordea_Pmt | AZ1: D_Nordea_Bal | BA1: D_DB_Pmt | BB1: D_DB_Bal | BC1: D_Aktia_Pmt | BD1: D_Aktia_Bal | BE1: D_HighAPR_Total | BF1: D_Scalable_Pmt | BG1: D_Scalable_Bal | BH1: D_AK_Pmt | BI1: D_AK_Bal | BJ1: D_Revolut_Pmt | BK1: D_C3_Pmt | BL1: D_Student_Pmt | BM1: D_IKEA_Pmt | BN1: D_N26_Pmt | BO1: D_Fixed_Total | BP1: Exp_Budget | BQ1: Exp_Alloc | BR1: Inv_Begin | BS1: Inv_OWNSAP | BT1: Inv_Excess | BU1: Inv_Growth | BV1: Inv_End | BW1: Cash_Begin | BX1: Cash_Add | BY1: Cash_End | BZ1: TaxRes_Beg | CA1: TaxRes_Add | CB1: TaxRes_End | CC1: H_TA_Hrs | CD1: W_TA_Hrs | CE1: NW_Invest | CF1: NW_House | CG1: NW_Mortgage | CH1: NW_Debt | CI1: NW_TA | CJ1: NW_Total
A2: 1 | B2: 2026 | C2: 01/2026 | D2: 12/2025 | E2: =IF(I2>0,"FAT_BONUS",IF(M2+U2>0,"FAT_RSU","LEAN")) -> LEAN | F2: =Salary_Schedule!E2 -> 7366.42 | G2: =Assumptions!$B$8 -> 200 | H2: =F2*Assumptions!$B$58 -> 736.642 | I2: =Salary_Schedule!F2 -> 0 | J2: =I2*Assumptions!$B$9 -> 0 | K2: =F2-G2-H2+I2-J2 -> 6429.778 | L2: =IF(COUNTIFS(SL_Income_Log!$B:$B,TEXT(B2,"0000")&"-"&TEXT(A2,"00"),SL_Income_Log!$C:$C,"salary",SL_Income_Log!$E:$E,"H")>0,SUMIFS(SL_Income_Log!$D:$D,SL_Income_Log!$B:$B,TEXT(B2,"0000")&"-"&TEXT(A2,"00"),SL_Income_Log!$C:$C,"salary",SL_Income_Log!$E:$E,"H"),K2*(1-Assumptions!$B$102)-Z2-Y2) -> 3487.4468 | M2: =0 -> 0 | N2: =Salary_Schedule!G2 -> 6195.67 | O2: =Assumptions!$B$19 -> 200 | P2: =N2*Assumptions!$B$59 -> 619.567 | Q2: =Salary_Schedule!H2 -> 0 | R2: =Q2*Assumptions!$B$20 -> 0 | S2: =N2-O2-P2+Q2-R2 -> 5376.103 | T2: =IF(COUNTIFS(SL_Income_Log!$B:$B,TEXT(B2,"0000")&"-"&TEXT(A2,"00"),SL_Income_Log!$C:$C,"salary",SL_Income_Log!$E:$E,"W")>0,SUMIFS(SL_Income_Log!$D:$D,SL_Income_Log!$B:$B,TEXT(B2,"0000")&"-"&TEXT(A2,"00"),SL_Income_Log!$C:$C,"salary",SL_Income_Log!$E:$E,"W"),S2*(1-Assumptions!$B$102)-AC2-AB2) -> 2855.2418 | U2: =0 -> 0 | V2: =H2*(1+Assumptions!$B$60)+Assumptions!$B$61 -> 1051.2988 | W2: =P2*(1+Assumptions!$B$60)+Assumptions!$B$61 -> 887.3938 | X2: =V2+W2 -> 1938.6926 | Y2: 78.75 | Z2: 291.67 | AA2: =26250-Z2 -> 25958.33 | AB2: 78.75 | AC2: 291.67 | AD2: =26250-AC2 -> 25958.33 | AE2: =Z2+AC2 -> 583.34 | AF2: =AA2+AD2 -> 51916.66 | AG2: =IF(COUNTIFS(SL_Income_Log!$B:$B,TEXT(B2,"0000")&"-"&TEXT(A2,"00"),SL_Income_Log!$C:$C,"youtube")>0,SUMIFS(SL_Income_Log!$D:$D,SL_Income_Log!$B:$B,TEXT(B2,"0000")&"-"&TEXT(A2,"00"),SL_Income_Log!$C:$C,"youtube"),MIN(Assumptions!$B$49+FLOOR((ROW()-2)/6,1)*Assumptions!$B$50,Assumptions!$B$51)) -> 1000 | AH2: =AG2*Assumptions!$B$104 -> 443 | AI2: =AG2-AH2 -> 557 | AJ2: =SUMIFS(SL_Income_Log!$D:$D,SL_Income_Log!$B:$B,TEXT(B2,"0000")&"-"&TEXT(A2,"00"),SL_Income_Log!$C:$C,"other") -> 0 | AK2: =0 -> 0 | AL2: =L2+M2+T2+U2+AI2+AJ2+IF((Debt_Register!$C$2+Debt_Register!$C$6+Debt_Register!$C$7+Debt_Register!$C$8+Debt_Register!$C$9)>5,X2,0) -> 8838.3812 | AM2: =AK2+AL2 -> 8838.3812 | AN2: =MAX(Assumptions!$B$94,MIN(Assumptions!$B$93,AM2-AP2-BE2-BO2-BQ2-Y2-Z2-AB2-AC2)) -> -740.84 | AO2: =Assumptions!$B$37-Assumptions!$B$38 -> 397546 | AP2: =IF(AO2>0,Assumptions!$B$33,0) -> 2281 | AQ2: =AO2*Assumptions!$B$32/12 -> 1288.7116 | AR2: =AP2-AQ2 -> 992.28838 | AS2: 0 | AT2: =MAX(0,AO2-AR2-AS2) -> 396553.71 | AU2: =IF(Debt_Register!$C$2>0,MIN(Debt_Register!$C$2,MAX(300,AM2-AP2-BO2-BQ2-AW2-AY2-BA2-BC2)),0) -> 585.3812 | AV2: =MAX(0,Debt_Register!$C$2-AU2) -> 8614.6188 | AW2: =IF(Debt_Register!$C$7>0,MIN(250,Debt_Register!$C$7),0) -> 250 | AX2: =MAX(0,Debt_Register!$C$7-AW2) -> 1750 | AY2: =IF(Debt_Register!$C$8>0,MIN(200,Debt_Register!$C$8),0) -> 200 | AZ2: =MAX(0,Debt_Register!$C$8-AY2) -> 1800 | BA2: =IF(AND(Debt_Register!$C$2<5,Debt_Register!$C$6>0),MIN(Debt_Register!$C$6,MAX(0,AM2-AP2-BO2-BQ2-AW2-AY2-BC2)),0) -> 0 | BB2: =MAX(0,Debt_Register!$C$6-BA2) -> 5500 | BC2: =IF(Debt_Register!$C$9>0,MIN(50,Debt_Register!$C$9),0) -> 50 | BD2: =MAX(0,Debt_Register!$C$9-BC2) -> 390 | BE2: =AU2+AW2+AY2+BA2+BC2 -> 1085.3812 | BF2: 0 | BG2: 5500 | BH2: 0 | BI2: 5000 | BJ2: =IF(OR(B2<Assumptions!$B$111,AND(B2=Assumptions!$B$111,A2<=Assumptions!$B$112)),Assumptions!$B$110,0) -> 650 | BK2: =MIN(Assumptions!$B$116+IF(OR(A2=4,A2=10),Assumptions!$B$117,0),10000) -> 290 | BL2: =IF(OR(B2<2030,AND(B2=2030,A2<8)),Assumptions!$B$118,IF(AND(B2=2030,A2=8),MOD(11000,200),0)) -> 200 | BM2: =IF(OR(B2<Assumptions!$B$120,AND(B2=Assumptions!$B$120,A2<=Assumptions!$B$121)),Assumptions!$B$119,0) -> 132 | BN2: =IF(AND(B2<=Assumptions!$B$123,A2<=Assumptions!$B$124),Assumptions!$B$122,0) -> 90 | BO2: =BF2+BH2+BJ2+BK2+BL2+BM2+BN2 -> 1362 | BP2: =SUMIFS(SL_Budget!$B:$B,SL_Budget!$C:$C,"'"&TEXT(DATE(B2,A2,1),"YYYY-MM")) -> 4110 | BQ2: =MAX(BP2, IFERROR(SUMIFS(ShadowLedger!D:D, ShadowLedger!C:C, ">="&DATE(B2,A2,1), ShadowLedger!C:C, "<"&EOMONTH(DATE(B2,A2,1),0)+1), 0)) -> 4110 | BR2: =Assumptions!$B$41 -> 12000 | BS2: =IF(Debt_Register!$C$2+Debt_Register!$C$7+Debt_Register!$C$8+Debt_Register!$C$3+Debt_Register!$C$9>5,0,X2) -> 0 | BT2: 0 | BU2: =(BR2+BS2+MAX(0,BT2))*(Assumptions!$B$43-1) -> 81.816 | BV2: =BR2+BS2+BT2+BU2 -> 12081.816 | BW2: =0 -> 0 | BX2: 0 | BY2: =BW2+BX2 -> 0 | BZ2: 0 | CA2: =AH2 -> 443 | CB2: =BZ2+CA2 -> 443 | CC2: =Assumptions!$B$24+(G2+J2)/(Salary_Schedule!E2*12/208) -> 1700.4706 | CD2: =Assumptions!$B$25+(O2+R2)/(Salary_Schedule!G2*12/208) -> 20.559531 | CE2: =BV2 -> 12081.816 | CF2: =Assumptions!$B$55*(1+Assumptions!$B$56)^((B2-2025)+(A2-1)/12) -> 527800 | CG2: =-AT2 -> -396553.71 | CH2: =-(AV2+AX2+BB2+AZ2+BD2+AF2+BG2+BI2) -> -80471.279 | CI2: =CC2*(Salary_Schedule!E2/173.33)*(1-Assumptions!$B$28)+CD2*(Salary_Schedule!G2/173.33)*(1-Assumptions!$B$28) -> 47452.515 | CJ2: =CE2+CF2+CG2+CH2+CI2 -> 110309.34
A3: 2 | B3: 2026 | C3: 02/2026 | D3: =C2 -> 01/2026 | E3: =IF(I3>0,"FAT_BONUS",IF(M3+U3>0,"FAT_RSU","LEAN")) -> LEAN | F3: =Salary_Schedule!E3 -> 7366.42 | G3: =Assumptions!$B$8 -> 200 | H3: =F3*Assumptions!$B$58 -> 736.642 | I3: =Salary_Schedule!F3 -> 0 | J3: =I3*Assumptions!$B$9 -> 0 | K3: =F3-G3-H3+I3-J3 -> 6429.778 | L3: =IF(COUNTIFS(SL_Income_Log!$B:$B,TEXT(B3,"0000")&"-"&TEXT(A3,"00"),SL_Income_Log!$C:$C,"salary",SL_Income_Log!$E:$E,"H")>0,SUMIFS(SL_Income_Log!$D:$D,SL_Income_Log!$B:$B,TEXT(B3,"0000")&"-"&TEXT(A3,"00"),SL_Income_Log!$C:$C,"salary",SL_Income_Log!$E:$E,"H"),K3*(1-Assumptions!$B$102)-Z3-Y3) -> 3488.3268 | M3: =RSU_Schedule!H2 -> 0 | N3: =Salary_Schedule!G3 -> 6195.67 | O3: =Assumptions!$B$19 -> 200 | P3: =N3*Assumptions!$B$59 -> 619.567 | Q3: =Salary_Schedule!H3 -> 0 | R3: =Q3*Assumptions!$B$20 -> 0 | S3: =N3-O3-P3+Q3-R3 -> 5376.103 | T3: =IF(COUNTIFS(SL_Income_Log!$B:$B,TEXT(B3,"0000")&"-"&TEXT(A3,"00"),SL_Income_Log!$C:$C,"salary",SL_Income_Log!$E:$E,"W")>0,SUMIFS(SL_Income_Log!$D:$D,SL_Income_Log!$B:$B,TEXT(B3,"0000")&"-"&TEXT(A3,"00"),SL_Income_Log!$C:$C,"salary",SL_Income_Log!$E:$E,"W"),S3*(1-Assumptions!$B$102)-AC3-AB3) -> 2856.1218 | U3: =RSU_Schedule!M2 -> 0 | V3: =H3*(1+Assumptions!$B$60)+Assumptions!$B$61 -> 1051.2988 | W3: =P3*(1+Assumptions!$B$60)+Assumptions!$B$61 -> 887.3938 | X3: =V3+W3 -> 1938.6926 | Y3: =ROUND(AA2*0.003,2) -> 77.87 | Z3: 291.67 | AA3: =MAX(0,AA2-Z3) -> 25666.66 | AB3: =ROUND(AD2*0.003,2) -> 77.87 | AC3: 291.67 | AD3: =MAX(0,AD2-AC3) -> 25666.66 | AE3: =Z3+AC3 -> 583.34 | AF3: =AA3+AD3 -> 51333.32 | AG3: =IF(COUNTIFS(SL_Income_Log!$B:$B,TEXT(B3,"0000")&"-"&TEXT(A3,"00"),SL_Income_Log!$C:$C,"youtube")>0,SUMIFS(SL_Income_Log!$D:$D,SL_Income_Log!$B:$B,TEXT(B3,"0000")&"-"&TEXT(A3,"00"),SL_Income_Log!$C:$C,"youtube"),MIN(Assumptions!$B$49+FLOOR((ROW()-2)/6,1)*Assumptions!$B$50,Assumptions!$B$51)) -> 1000 | AH3: =AG3*Assumptions!$B$104 -> 443 | AI3: =AG3-AH3 -> 557 | AJ3: =SUMIFS(SL_Income_Log!$D:$D,SL_Income_Log!$B:$B,TEXT(B3,"0000")&"-"&TEXT(A3,"00"),SL_Income_Log!$C:$C,"other") -> 0 | AK3: =AN2 -> -740.84 | AL3: =L3+M3+T3+U3+AI3+AJ3-Y3-Z3-AB3-AC3+IF((Debt_Register!$C$2+Debt_Register!$C$6+Debt_Register!$C$7+Debt_Register!$C$8+Debt_Register!$C$9)>5,X3,0) -> 8101.0612 | AM3: =AK3+AL3 -> 7360.2212 | AN3: =MAX(Assumptions!$B$94,MIN(Assumptions!$B$93,AM3-AP3-BE3-BO3-BQ3)) -> -1000 | AO3: =AT2 -> 396553.71 | AP3: =IF(AO3>0,Assumptions!$B$33,0) -> 2281 | AQ3: =AO3*Assumptions!$B$32/12 -> 1285.4949 | AR3: =AP3-AQ3 -> 995.50505 | AS3: =IF(AND((AV2+AX2+AZ2+BB2+BD2)<5,AO3>0,SUMIF($B$2:B2,B3,$AS$2:AS2)=0,(MAX(0,AN3-10000)+MAX(0,BY2-5000)+MAX(0,BV2-20000))>=21550),21550,0) -> 0 | AT3: =MAX(0,AO3-AR3-AS3) -> 395558.21 | AU3: =IF(AV2>0,MIN(AV2,MAX(300,AM3-AP3-BO3-BQ3-AW3-AY3-BA3-BC3)),0) -> 300 | AV3: =MAX(0,AV2-AU3) -> 8314.6188 | AW3: =IF(AX2>0,MIN(250,AX2),0) -> 250 | AX3: =MAX(0,AX2-AW3) -> 1500 | AY3: =IF(AZ2>0,MIN(200,AZ2),0) -> 200 | AZ3: =MAX(0,AZ2-AY3) -> 1600 | BA3: =IF(AND(AV2<5,BB2>0),MIN(BB2,MAX(0,AM3-AP3-BO3-BQ3-AW3-AY3-BC3)),0) -> 0 | BB3: =MAX(0,BB2-BA3) -> 5500 | BC3: =IF(BD2>0,MIN(50,BD2),0) -> 50 | BD3: =MAX(0,BD2-BC3) -> 340 | BE3: =AU3+AW3+AY3+BA3+BC3 -> 800 | BF3: 0 | BG3: =MAX(0,BG2-BF3) -> 5500 | BH3: 0 | BI3: =MAX(0,BI2-BH3) -> 5000 | BJ3: =IF(OR(B3<Assumptions!$B$111,AND(B3=Assumptions!$B$111,A3<=Assumptions!$B$112)),Assumptions!$B$110,0) -> 650 | BK3: =IF(B3<2027,Assumptions!$B$116+IF(OR(A3=4,A3=10),Assumptions!$B$117,0),IF(AND(B3=2027,A3<=4),IF(A3=4,MIN(950,Assumptions!$B$116+Assumptions!$B$117),Assumptions!$B$116),0)) -> 290 | BL3: =IF(OR(B3<2030,AND(B3=2030,A3<8)),Assumptions!$B$118,IF(AND(B3=2030,A3=8),MOD(11000,200),0)) -> 200 | BM3: =IF(OR(B3<Assumptions!$B$120,AND(B3=Assumptions!$B$120,A3<=Assumptions!$B$121)),Assumptions!$B$119,0) -> 132 | BN3: =IF(AND(B3<=Assumptions!$B$123,A3<=Assumptions!$B$124),Assumptions!$B$122,0) -> 90 | BO3: =BF3+BH3+BJ3+BK3+BL3+BM3+BN3 -> 1362 | BP3: =SUMIFS(SL_Budget!$B:$B,SL_Budget!$C:$C,"'"&TEXT(DATE(B3,A3,1),"YYYY-MM")) -> 4110 | BQ3: =MAX(BP3, IFERROR(SUMIFS(ShadowLedger!D:D, ShadowLedger!C:C, ">="&DATE(B3,A3,1), ShadowLedger!C:C, "<"&EOMONTH(DATE(B3,A3,1),0)+1), 0)) -> 4110 | BR3: =BV2 -> 12081.816 | BS3: =IF((AV2+AX2+BB2+AZ2+BD2)>5,0,X3) -> 0 | BT3: =IF(AS3>0,-MAX(0,21550-MAX(0,MAX(0,(AM3-AP3-BE3-BO3-BQ3)-Assumptions!$B$93))-MIN(MAX(0,21550-MAX(0,MAX(0,(AM3-AP3-BE3-BO3-BQ3)-Assumptions!$B$93))),MAX(0,BY2-Assumptions!$B$91))),IF(BY2>=Assumptions!$B$92,MAX(0,(AM3-AP3-BE3-BO3-BQ3)-Assumptions!$B$93),MAX(0,(AM3-AP3-BE3-BO3-BQ3)-Assumptions!$B$93)*Assumptions!$B$99)) -> 0 | BU3: =(BR3+BS3+MAX(0,BT3))*(Assumptions!$B$43-1) -> 82.373821 | BV3: =BR3+BS3+BT3+BU3 -> 12164.19 | BW3: =BY2 -> 0 | BX3: =IF(AS3>0,-MIN(MAX(0,21550-MAX(0,MAX(0,(AM3-AP3-BE3-BO3-BQ3)-Assumptions!$B$93))),MAX(0,BY2-Assumptions!$B$91)),IF(BY2<Assumptions!$B$92,MAX(0,(AM3-AP3-BE3-BO3-BQ3)-Assumptions!$B$93)*Assumptions!$B$98,0)) -> 0 | BY3: =BW3+BX3 -> 0 | BZ3: =IF(A3=1,0,CB2) -> 443 | CA3: =AH3 -> 443 | CB3: =BZ3+CA3 -> 886 | CC3: =CC2+(G3+J3)/(Salary_Schedule!E3*12/208) -> 1700.9412 | CD3: =CD2+(O3+R3)/(Salary_Schedule!G3*12/208) -> 21.119061 | CE3: =BV3 -> 12164.19 | CF3: =Assumptions!$B$55*(1+Assumptions!$B$56)^((B3-2025)+(A3-1)/12) -> 528455.26 | CG3: =-AT3 -> -395558.21 | CH3: =-(AV3+AX3+BB3+AZ3+BD3+AF3+BG3+BI3) -> -79087.939 | CI3: =CC3*(Salary_Schedule!E3/173.33)*(1-Assumptions!$B$28)+CD3*(Salary_Schedule!G3/173.33)*(1-Assumptions!$B$28) -> 47478.516 | CJ3: =CE3+CF3+CG3+CH3+CI3 -> 113451.82
A4: 3 | B4: 2026 | C4: 03/2026 | D4: =C3 -> 02/2026 | E4: =IF(I4>0,"FAT_BONUS",IF(M4+U4>0,"FAT_RSU","LEAN")) -> LEAN | F4: =Salary_Schedule!E4 -> 7366.42 | G4: =Assumptions!$B$8 -> 200 | H4: =F4*Assumptions!$B$58 -> 736.642 | I4: =Salary_Schedule!F4 -> 0 | J4: =I4*Assumptions!$B$9 -> 0 | K4: =F4-G4-H4+I4-J4 -> 6429.778 | L4: =IF(COUNTIFS(SL_Income_Log!$B:$B,TEXT(B4,"0000")&"-"&TEXT(A4,"00"),SL_Income_Log!$C:$C,"salary",SL_Income_Log!$E:$E,"H")>0,SUMIFS(SL_Income_Log!$D:$D,SL_Income_Log!$B:$B,TEXT(B4,"0000")&"-"&TEXT(A4,"00"),SL_Income_Log!$C:$C,"salary",SL_Income_Log!$E:$E,"H"),K4*(1-Assumptions!$B$102)-Z4-Y4) -> 3489.1968 | M4: =RSU_Schedule!H3 -> 0 | N4: =Salary_Schedule!G4 -> 6195.67 | O4: =Assumptions!$B$19 -> 200 | P4: =N4*Assumptions!$B$59 -> 619.567 | Q4: =Salary_Schedule!H4 -> 0 | R4: =Q4*Assumptions!$B$20 -> 0 | S4: =N4-O4-P4+Q4-R4 -> 5376.103 | T4: =IF(COUNTIFS(SL_Income_Log!$B:$B,TEXT(B4,"0000")&"-"&TEXT(A4,"00"),SL_Income_Log!$C:$C,"salary",SL_Income_Log!$E:$E,"W")>0,SUMIFS(SL_Income_Log!$D:$D,SL_Income_Log!$B:$B,TEXT(B4,"0000")&"-"&TEXT(A4,"00"),SL_Income_Log!$C:$C,"salary",SL_Income_Log!$E:$E,"W"),S4*(1-Assumptions!$B$102)-AC4-AB4) -> 2856.9918 | U4: =RSU_Schedule!M3 -> 0 | V4: =H4*(1+Assumptions!$B$60)+Assumptions!$B$61 -> 1051.2988 | W4: =P4*(1+Assumptions!$B$60)+Assumptions!$B$61 -> 887.3938 | X4: =V4+W4 -> 1938.6926 | Y4: =ROUND(AA3*0.003,2) -> 77 | Z4: 291.67 | AA4: =MAX(0,AA3-Z4) -> 25374.99 | AB4: =ROUND(AD3*0.003,2) -> 77 | AC4: 291.67 | AD4: =MAX(0,AD3-AC4) -> 25374.99 | AE4: =Z4+AC4 -> 583.34 | AF4: =AA4+AD4 -> 50749.98 | AG4: =IF(COUNTIFS(SL_Income_Log!$B:$B,TEXT(B4,"0000")&"-"&TEXT(A4,"00"),SL_Income_Log!$C:$C,"youtube")>0,SUMIFS(SL_Income_Log!$D:$D,SL_Income_Log!$B:$B,TEXT(B4,"0000")&"-"&TEXT(A4,"00"),SL_Income_Log!$C:$C,"youtube"),MIN(Assumptions!$B$49+FLOOR((ROW()-2)/6,1)*Assumptions!$B$50,Assumptions!$B$51)) -> 1000 | AH4: =AG4*Assumptions!$B$104 -> 443 | AI4: =AG4-AH4 -> 557 | AJ4: =SUMIFS(SL_Income_Log!$D:$D,SL_Income_Log!$B:$B,TEXT(B4,"0000")&"-"&TEXT(A4,"00"),SL_Income_Log!$C:$C,"other") -> 0 | AK4: =AN3 -> -1000 | AL4: =L4+M4+T4+U4+AI4+AJ4-Y4-Z4-AB4-AC4+IF((Debt_Register!$C$2+Debt_Register!$C$6+Debt_Register!$C$7+Debt_Register!$C$8+Debt_Register!$C$9)>5,X4,0) -> 8104.5412 | AM4: =AK4+AL4 -> 7104.5412 | AN4: =MAX(Assumptions!$B$94,MIN(Assumptions!$B$93,AM4-AP4-BE4-BO4-BQ4)) -> -1000 | AO4: =AT3 -> 395558.21 | AP4: =IF(AO4>0,Assumptions!$B$33,0) -> 2281 | AQ4: =AO4*Assumptions!$B$32/12 -> 1282.2679 | AR4: =AP4-AQ4 -> 998.73215 | AS4: =IF(AND((AV3+AX3+AZ3+BB3+BD3)<5,AO4>0,SUMIF($B$2:B3,B4,$AS$2:AS3)=0,(MAX(0,AN4-10000)+MAX(0,BY3-5000)+MAX(0,BV3-20000))>=21550),21550,0) -> 0 | AT4: =MAX(0,AO4-AR4-AS4) -> 394559.47 | AU4: =IF(AV3>0,MIN(AV3,MAX(300,AM4-AP4-BO4-BQ4-AW4-AY4-BA4-BC4)),0) -> 300 | AV4: =MAX(0,AV3-AU4) -> 8014.6188 | AW4: =IF(AX3>0,MIN(250,AX3),0) -> 250 | AX4: =MAX(0,AX3-AW4) -> 1250 | AY4: =IF(AZ3>0,MIN(200,AZ3),0) -> 200 | AZ4: =MAX(0,AZ3-AY4) -> 1400 | BA4: =IF(AND(AV3<5,BB3>0),MIN(BB3,MAX(0,AM4-AP4-BO4-BQ4-AW4-AY4-BC4)),0) -> 0 | BB4: =MAX(0,BB3-BA4) -> 5500 | BC4: =IF(BD3>0,MIN(50,BD3),0) -> 50 | BD4: =MAX(0,BD3-BC4) -> 290 | BE4: =AU4+AW4+AY4+BA4+BC4 -> 800 | BF4: 0 | BG4: =MAX(0,BG3-BF4) -> 5500 | BH4: 0 | BI4: =MAX(0,BI3-BH4) -> 5000 | BJ4: =IF(OR(B4<Assumptions!$B$111,AND(B4=Assumptions!$B$111,A4<=Assumptions!$B$112)),Assumptions!$B$110,0) -> 650 | BK4: =IF(B4<2027,Assumptions!$B$116+IF(OR(A4=4,A4=10),Assumptions!$B$117,0),IF(AND(B4=2027,A4<=4),IF(A4=4,MIN(950,Assumptions!$B$116+Assumptions!$B$117),Assumptions!$B$116),0)) -> 290 | BL4: =IF(OR(B4<2030,AND(B4=2030,A4<8)),Assumptions!$B$118,IF(AND(B4=2030,A4=8),MOD(11000,200),0)) -> 200 | BM4: =IF(OR(B4<Assumptions!$B$120,AND(B4=Assumptions!$B$120,A4<=Assumptions!$B$121)),Assumptions!$B$119,0) -> 132 | BN4: =IF(AND(B4<=Assumptions!$B$123,A4<=Assumptions!$B$124),Assumptions!$B$122,0) -> 90 | BO4: =BF4+BH4+BJ4+BK4+BL4+BM4+BN4 -> 1362 | BP4: =SUMIFS(SL_Budget!$B:$B,SL_Budget!$C:$C,"'"&TEXT(DATE(B4,A4,1),"YYYY-MM")) -> 4110 | BQ4: =MAX(BP4, IFERROR(SUMIFS(ShadowLedger!D:D, ShadowLedger!C:C, ">="&DATE(B4,A4,1), ShadowLedger!C:C, "<"&EOMONTH(DATE(B4,A4,1),0)+1), 0)) -> 4110 | BR4: =BV3 -> 12164.19 | BS4: =IF((AV3+AX3+BB3+AZ3+BD3)>5,0,X4) -> 0 | BT4: =IF(AS4>0,-MAX(0,21550-MAX(0,MAX(0,(AM4-AP4-BE4-BO4-BQ4)-Assumptions!$B$93))-MIN(MAX(0,21550-MAX(0,MAX(0,(AM4-AP4-BE4-BO4-BQ4)-Assumptions!$B$93))),MAX(0,BY3-Assumptions!$B$91))),IF(BY3>=Assumptions!$B$92,MAX(0,(AM4-AP4-BE4-BO4-BQ4)-Assumptions!$B$93),MAX(0,(AM4-AP4-BE4-BO4-BQ4)-Assumptions!$B$93)*Assumptions!$B$99)) -> 0 | BU4: =(BR4+BS4+MAX(0,BT4))*(Assumptions!$B$43-1) -> 82.935446 | BV4: =BR4+BS4+BT4+BU4 -> 12247.125 | BW4: =BY3 -> 0 | BX4: =IF(AS4>0,-MIN(MAX(0,21550-MAX(0,MAX(0,(AM4-AP4-BE4-BO4-BQ4)-Assumptions!$B$93))),MAX(0,BY3-Assumptions!$B$91)),IF(BY3<Assumptions!$B$92,MAX(0,(AM4-AP4-BE4-BO4-BQ4)-Assumptions!$B$93)*Assumptions!$B$98,0)) -> 0 | BY4: =BW4+BX4 -> 0 | BZ4: =IF(A4=1,0,CB3) -> 886 | CA4: =AH4 -> 443 | CB4: =BZ4+CA4 -> 1329 | CC4: =CC3+(G4+J4)/(Salary_Schedule!E4*12/208) -> 1701.4118 | CD4: =CD3+(O4+R4)/(Salary_Schedule!G4*12/208) -> 21.678592 | CE4: =BV4 -> 12247.125 | CF4: =Assumptions!$B$55*(1+Assumptions!$B$56)^((B4-2025)+(A4-1)/12) -> 529111.33 | CG4: =-AT4 -> -394559.47 | CH4: =-(AV4+AX4+BB4+AZ4+BD4+AF4+BG4+BI4) -> -77704.599 | CI4: =CC4*(Salary_Schedule!E4/173.33)*(1-Assumptions!$B$28)+CD4*(Salary_Schedule!G4/173.33)*(1-Assumptions!$B$28) -> 47504.516 | CJ4: =CE4+CF4+CG4+CH4+CI4 -> 116598.9
A5: 4 | B5: 2026 | C5: 04/2026 | D5: =C4 -> 03/2026 | E5: =IF(I5>0,"FAT_BONUS",IF(M5+U5>0,"FAT_RSU","LEAN")) -> FAT_BONUS | F5: =Salary_Schedule!E5 -> 7366.42 | G5: =Assumptions!$B$8 -> 200 | H5: =F5*Assumptions!$B$58 -> 736.642 | I5: =Salary_Schedule!F5 -> 9821 | J5: =I5*Assumptions!$B$9 -> 3437.35 | K5: =F5-G5-H5+I5-J5 -> 12813.428 | L5: =IF(COUNTIFS(SL_Income_Log!$B:$B,TEXT(B5,"0000")&"-"&TEXT(A5,"00"),SL_Income_Log!$C:$C,"salary",SL_Income_Log!$E:$E,"H")>0,SUMIFS(SL_Income_Log!$D:$D,SL_Income_Log!$B:$B,TEXT(B5,"0000")&"-"&TEXT(A5,"00"),SL_Income_Log!$C:$C,"salary",SL_Income_Log!$E:$E,"H"),K5*(1-Assumptions!$B$102)-Z5-Y5) -> 7320.2668 | M5: =RSU_Schedule!H4 -> 4788.75 | N5: =Salary_Schedule!G5 -> 6195.67 | O5: =Assumptions!$B$19 -> 200 | P5: =N5*Assumptions!$B$59 -> 619.567 | Q5: =Salary_Schedule!H5 -> 8261 | R5: =Q5*Assumptions!$B$20 -> 2891.35 | S5: =N5-O5-P5+Q5-R5 -> 10745.753 | T5: =IF(COUNTIFS(SL_Income_Log!$B:$B,TEXT(B5,"0000")&"-"&TEXT(A5,"00"),SL_Income_Log!$C:$C,"salary",SL_Income_Log!$E:$E,"W")>0,SUMIFS(SL_Income_Log!$D:$D,SL_Income_Log!$B:$B,TEXT(B5,"0000")&"-"&TEXT(A5,"00"),SL_Income_Log!$C:$C,"salary",SL_Income_Log!$E:$E,"W"),S5*(1-Assumptions!$B$102)-AC5-AB5) -> 6079.6618 | U5: =RSU_Schedule!M4 -> 2394.38 | V5: =H5*(1+Assumptions!$B$60)+Assumptions!$B$61 -> 1051.2988 | W5: =P5*(1+Assumptions!$B$60)+Assumptions!$B$61 -> 887.3938 | X5: =V5+W5 -> 1938.6926 | Y5: =ROUND(AA4*0.003,2) -> 76.12 | Z5: 291.67 | AA5: =MAX(0,AA4-Z5) -> 25083.32 | AB5: =ROUND(AD4*0.003,2) -> 76.12 | AC5: 291.67 | AD5: =MAX(0,AD4-AC5) -> 25083.32 | AE5: =Z5+AC5 -> 583.34 | AF5: =AA5+AD5 -> 50166.64 | AG5: =IF(COUNTIFS(SL_Income_Log!$B:$B,TEXT(B5,"0000")&"-"&TEXT(A5,"00"),SL_Income_Log!$C:$C,"youtube")>0,SUMIFS(SL_Income_Log!$D:$D,SL_Income_Log!$B:$B,TEXT(B5,"0000")&"-"&TEXT(A5,"00"),SL_Income_Log!$C:$C,"youtube"),MIN(Assumptions!$B$49+FLOOR((ROW()-2)/6,1)*Assumptions!$B$50,Assumptions!$B$51)) -> 1000 | AH5: =AG5*Assumptions!$B$104 -> 443 | AI5: =AG5-AH5 -> 557 | AJ5: =SUMIFS(SL_Income_Log!$D:$D,SL_Income_Log!$B:$B,TEXT(B5,"0000")&"-"&TEXT(A5,"00"),SL_Income_Log!$C:$C,"other") -> 0 | AK5: =AN4 -> -1000 | AL5: =L5+M5+T5+U5+AI5+AJ5-Y5-Z5-AB5-AC5+IF((Debt_Register!$C$2+Debt_Register!$C$6+Debt_Register!$C$7+Debt_Register!$C$8+Debt_Register!$C$9)>5,X5,0) -> 22343.171 | AM5: =AK5+AL5 -> 21343.171 | AN5: =MAX(Assumptions!$B$94,MIN(Assumptions!$B$93,AM5-AP5-BE5-BO5-BQ5)) -> 2725.5524 | AO5: =AT4 -> 394559.47 | AP5: =IF(AO5>0,Assumptions!$B$33,0) -> 2281 | AQ5: =AO5*Assumptions!$B$32/12 -> 1279.0303 | AR5: =AP5-AQ5 -> 1001.9697 | AS5: =IF(AND((AV4+AX4+AZ4+BB4+BD4)<5,AO5>0,SUMIF($B$2:B4,B5,$AS$2:AS4)=0,(MAX(0,AN5-10000)+MAX(0,BY4-5000)+MAX(0,BV4-20000))>=21550),21550,0) -> 0 | AT5: =MAX(0,AO5-AR5-AS5) -> 393557.5 | AU5: =IF(AV4>0,MIN(AV4,MAX(300,AM5-AP5-BO5-BQ5-AW5-AY5-BA5-BC5)),0) -> 8014.6188 | AV5: =MAX(0,AV4-AU5) -> 0 | AW5: =IF(AX4>0,MIN(250,AX4),0) -> 250 | AX5: =MAX(0,AX4-AW5) -> 1000 | AY5: =IF(AZ4>0,MIN(200,AZ4),0) -> 200 | AZ5: =MAX(0,AZ4-AY5) -> 1200 | BA5: =IF(AND(AV4<5,BB4>0),MIN(BB4,MAX(0,AM5-AP5-BO5-BQ5-AW5-AY5-BC5)),0) -> 0 | BB5: =MAX(0,BB4-BA5) -> 5500 | BC5: =IF(BD4>0,MIN(50,BD4),0) -> 50 | BD5: =MAX(0,BD4-BC5) -> 240 | BE5: =AU5+AW5+AY5+BA5+BC5 -> 8514.6188 | BF5: 0 | BG5: =MAX(0,BG4-BF5) -> 5500 | BH5: 0 | BI5: =MAX(0,BI4-BH5) -> 5000 | BJ5: =IF(OR(B5<Assumptions!$B$111,AND(B5=Assumptions!$B$111,A5<=Assumptions!$B$112)),Assumptions!$B$110,0) -> 650 | BK5: =IF(B5<2027,Assumptions!$B$116+IF(OR(A5=4,A5=10),Assumptions!$B$117,0),IF(AND(B5=2027,A5<=4),IF(A5=4,MIN(950,Assumptions!$B$116+Assumptions!$B$117),Assumptions!$B$116),0)) -> 2640 | BL5: =IF(OR(B5<2030,AND(B5=2030,A5<8)),Assumptions!$B$118,IF(AND(B5=2030,A5=8),MOD(11000,200),0)) -> 200 | BM5: =IF(OR(B5<Assumptions!$B$120,AND(B5=Assumptions!$B$120,A5<=Assumptions!$B$121)),Assumptions!$B$119,0) -> 132 | BN5: =IF(AND(B5<=Assumptions!$B$123,A5<=Assumptions!$B$124),Assumptions!$B$122,0) -> 90 | BO5: =BF5+BH5+BJ5+BK5+BL5+BM5+BN5 -> 3712 | BP5: =SUMIFS(SL_Budget!$B:$B,SL_Budget!$C:$C,"'"&TEXT(DATE(B5,A5,1),"YYYY-MM")) -> 4110 | BQ5: =MAX(BP5, IFERROR(SUMIFS(ShadowLedger!D:D, ShadowLedger!C:C, ">="&DATE(B5,A5,1), ShadowLedger!C:C, "<"&EOMONTH(DATE(B5,A5,1),0)+1), 0)) -> 4110 | BR5: =BV4 -> 12247.125 | BS5: =IF((AV4+AX4+BB4+AZ4+BD4)>5,0,X5) -> 0 | BT5: =IF(AS5>0,-MAX(0,21550-MAX(0,MAX(0,(AM5-AP5-BE5-BO5-BQ5)-Assumptions!$B$93))-MIN(MAX(0,21550-MAX(0,MAX(0,(AM5-AP5-BE5-BO5-BQ5)-Assumptions!$B$93))),MAX(0,BY4-Assumptions!$B$91))),IF(BY4>=Assumptions!$B$92,MAX(0,(AM5-AP5-BE5-BO5-BQ5)-Assumptions!$B$93),MAX(0,(AM5-AP5-BE5-BO5-BQ5)-Assumptions!$B$93)*Assumptions!$B$99)) -> 0 | BU5: =(BR5+BS5+MAX(0,BT5))*(Assumptions!$B$43-1) -> 83.5009 | BV5: =BR5+BS5+BT5+BU5 -> 12330.626 | BW5: =BY4 -> 0 | BX5: =IF(AS5>0,-MIN(MAX(0,21550-MAX(0,MAX(0,(AM5-AP5-BE5-BO5-BQ5)-Assumptions!$B$93))),MAX(0,BY4-Assumptions!$B$91)),IF(BY4<Assumptions!$B$92,MAX(0,(AM5-AP5-BE5-BO5-BQ5)-Assumptions!$B$93)*Assumptions!$B$98,0)) -> 0 | BY5: =BW5+BX5 -> 0 | BZ5: =IF(A5=1,0,CB4) -> 1329 | CA5: =AH5 -> 443 | CB5: =BZ5+CA5 -> 1772 | CC5: =CC4+(G5+J5)/(Salary_Schedule!E5*12/208) -> 1709.9706 | CD5: =CD4+(O5+R5)/(Salary_Schedule!G5*12/208) -> 30.327116 | CE5: =BV5 -> 12330.626 | CF5: =Assumptions!$B$55*(1+Assumptions!$B$56)^((B5-2025)+(A5-1)/12) -> 529768.21 | CG5: =-AT5 -> -393557.5 | CH5: =-(AV5+AX5+BB5+AZ5+BD5+AF5+BG5+BI5) -> -68606.64 | CI5: =CC5*(Salary_Schedule!E5/173.33)*(1-Assumptions!$B$28)+CD5*(Salary_Schedule!G5/173.33)*(1-Assumptions!$B$28) -> 47941.89 | CJ5: =CE5+CF5+CG5+CH5+CI5 -> 127876.58
A6: 5 | B6: 2026 | C6: 05/2026 | D6: =C5 -> 04/2026 | E6: =IF(I6>0,"FAT_BONUS",IF(M6+U6>0,"FAT_RSU","LEAN")) -> LEAN | F6: =Salary_Schedule!E6 -> 7366.42 | G6: =Assumptions!$B$8 -> 200 | H6: =F6*Assumptions!$B$58 -> 736.642 | I6: =Salary_Schedule!F6 -> 0 | J6: =I6*Assumptions!$B$9 -> 0 | K6: =F6-G6-H6+I6-J6 -> 6429.778 | L6: =IF(COUNTIFS(SL_Income_Log!$B:$B,TEXT(B6,"0000")&"-"&TEXT(A6,"00"),SL_Income_Log!$C:$C,"salary",SL_Income_Log!$E:$E,"H")>0,SUMIFS(SL_Income_Log!$D:$D,SL_Income_Log!$B:$B,TEXT(B6,"0000")&"-"&TEXT(A6,"00"),SL_Income_Log!$C:$C,"salary",SL_Income_Log!$E:$E,"H"),K6*(1-Assumptions!$B$102)-Z6-Y6) -> 3490.9468 | M6: =RSU_Schedule!H5 -> 0 | N6: =Salary_Schedule!G6 -> 6195.67 | O6: =Assumptions!$B$19 -> 200 | P6: =N6*Assumptions!$B$59 -> 619.567 | Q6: =Salary_Schedule!H6 -> 0 | R6: =Q6*Assumptions!$B$20 -> 0 | S6: =N6-O6-P6+Q6-R6 -> 5376.103 | T6: =IF(COUNTIFS(SL_Income_Log!$B:$B,TEXT(B6,"0000")&"-"&TEXT(A6,"00"),SL_Income_Log!$C:$C,"salary",SL_Income_Log!$E:$E,"W")>0,SUMIFS(SL_Income_Log!$D:$D,SL_Income_Log!$B:$B,TEXT(B6,"0000")&"-"&TEXT(A6,"00"),SL_Income_Log!$C:$C,"salary",SL_Income_Log!$E:$E,"W"),S6*(1-Assumptions!$B$102)-AC6-AB6) -> 2858.7418 | U6: =RSU_Schedule!M5 -> 0 | V6: =H6*(1+Assumptions!$B$60)+Assumptions!$B$61 -> 1051.2988 | W6: =P6*(1+Assumptions!$B$60)+Assumptions!$B$61 -> 887.3938 | X6: =V6+W6 -> 1938.6926 | Y6: =ROUND(AA5*0.003,2) -> 75.25 | Z6: 291.67 | AA6: =MAX(0,AA5-Z6) -> 24791.65 | AB6: =ROUND(AD5*0.003,2) -> 75.25 | AC6: 291.67 | AD6: =MAX(0,AD5-AC6) -> 24791.65 | AE6: =Z6+AC6 -> 583.34 | AF6: =AA6+AD6 -> 49583.3 | AG6: =IF(COUNTIFS(SL_Income_Log!$B:$B,TEXT(B6,"0000")&"-"&TEXT(A6,"00"),SL_Income_Log!$C:$C,"youtube")>0,SUMIFS(SL_Income_Log!$D:$D,SL_Income_Log!$B:$B,TEXT(B6,"0000")&"-"&TEXT(A6,"00"),SL_Income_Log!$C:$C,"youtube"),MIN(Assumptions!$B$49+FLOOR((ROW()-2)/6,1)*Assumptions!$B$50,Assumptions!$B$51)) -> 1000 | AH6: =AG6*Assumptions!$B$104 -> 443 | AI6: =AG6-AH6 -> 557 | AJ6: =SUMIFS(SL_Income_Log!$D:$D,SL_Income_Log!$B:$B,TEXT(B6,"0000")&"-"&TEXT(A6,"00"),SL_Income_Log!$C:$C,"other") -> 0 | AK6: =AN5 -> 2725.5524 | AL6: =L6+M6+T6+U6+AI6+AJ6-Y6-Z6-AB6-AC6+IF((Debt_Register!$C$2+Debt_Register!$C$6+Debt_Register!$C$7+Debt_Register!$C$8+Debt_Register!$C$9)>5,X6,0) -> 8111.5412 | AM6: =AK6+AL6 -> 10837.094 | AN6: =MAX(Assumptions!$B$94,MIN(Assumptions!$B$93,AM6-AP6-BE6-BO6-BQ6)) -> 0 | AO6: =AT5 -> 393557.5 | AP6: =IF(AO6>0,Assumptions!$B$33,0) -> 2281 | AQ6: =AO6*Assumptions!$B$32/12 -> 1275.7822 | AR6: =AP6-AQ6 -> 1005.2178 | AS6: =IF(AND((AV5+AX5+AZ5+BB5+BD5)<5,AO6>0,SUMIF($B$2:B5,B6,$AS$2:AS5)=0,(MAX(0,AN6-10000)+MAX(0,BY5-5000)+MAX(0,BV5-20000))>=21550),21550,0) -> 0 | AT6: =MAX(0,AO6-AR6-AS6) -> 392552.29 | AU6: =IF(AV5>0,MIN(AV5,MAX(300,AM6-AP6-BO6-BQ6-AW6-AY6-BA6-BC6)),0) -> 0 | AV6: =MAX(0,AV5-AU6) -> 0 | AW6: =IF(AX5>0,MIN(250,AX5),0) -> 250 | AX6: =MAX(0,AX5-AW6) -> 750 | AY6: =IF(AZ5>0,MIN(200,AZ5),0) -> 200 | AZ6: =MAX(0,AZ5-AY6) -> 1000 | BA6: =IF(AND(AV5<5,BB5>0),MIN(BB5,MAX(0,AM6-AP6-BO6-BQ6-AW6-AY6-BC6)),0) -> 2674.0936 | BB6: =MAX(0,BB5-BA6) -> 2825.9064 | BC6: =IF(BD5>0,MIN(50,BD5),0) -> 50 | BD6: =MAX(0,BD5-BC6) -> 190 | BE6: =AU6+AW6+AY6+BA6+BC6 -> 3174.0936 | BF6: 0 | BG6: =MAX(0,BG5-BF6) -> 5500 | BH6: 0 | BI6: =MAX(0,BI5-BH6) -> 5000 | BJ6: =IF(OR(B6<Assumptions!$B$111,AND(B6=Assumptions!$B$111,A6<=Assumptions!$B$112)),Assumptions!$B$110,0) -> 650 | BK6: =IF(B6<2027,Assumptions!$B$116+IF(OR(A6=4,A6=10),Assumptions!$B$117,0),IF(AND(B6=2027,A6<=4),IF(A6=4,MIN(950,Assumptions!$B$116+Assumptions!$B$117),Assumptions!$B$116),0)) -> 290 | BL6: =IF(OR(B6<2030,AND(B6=2030,A6<8)),Assumptions!$B$118,IF(AND(B6=2030,A6=8),MOD(11000,200),0)) -> 200 | BM6: =IF(OR(B6<Assumptions!$B$120,AND(B6=Assumptions!$B$120,A6<=Assumptions!$B$121)),Assumptions!$B$119,0) -> 132 | BN6: =IF(AND(B6<=Assumptions!$B$123,A6<=Assumptions!$B$124),Assumptions!$B$122,0) -> 0 | BO6: =BF6+BH6+BJ6+BK6+BL6+BM6+BN6 -> 1272 | BP6: =SUMIFS(SL_Budget!$B:$B,SL_Budget!$C:$C,"'"&TEXT(DATE(B6,A6,1),"YYYY-MM")) -> 4110 | BQ6: =MAX(BP6, IFERROR(SUMIFS(ShadowLedger!D:D, ShadowLedger!C:C, ">="&DATE(B6,A6,1), ShadowLedger!C:C, "<"&EOMONTH(DATE(B6,A6,1),0)+1), 0)) -> 4110 | BR6: =BV5 -> 12330.626 | BS6: =IF((AV5+AX5+BB5+AZ5+BD5)>5,0,X6) -> 0 | BT6: =IF(AS6>0,-MAX(0,21550-MAX(0,MAX(0,(AM6-AP6-BE6-BO6-BQ6)-Assumptions!$B$93))-MIN(MAX(0,21550-MAX(0,MAX(0,(AM6-AP6-BE6-BO6-BQ6)-Assumptions!$B$93))),MAX(0,BY5-Assumptions!$B$91))),IF(BY5>=Assumptions!$B$92,MAX(0,(AM6-AP6-BE6-BO6-BQ6)-Assumptions!$B$93),MAX(0,(AM6-AP6-BE6-BO6-BQ6)-Assumptions!$B$93)*Assumptions!$B$99)) -> 0 | BU6: =(BR6+BS6+MAX(0,BT6))*(Assumptions!$B$43-1) -> 84.070209 | BV6: =BR6+BS6+BT6+BU6 -> 12414.696 | BW6: =BY5 -> 0 | BX6: =IF(AS6>0,-MIN(MAX(0,21550-MAX(0,MAX(0,(AM6-AP6-BE6-BO6-BQ6)-Assumptions!$B$93))),MAX(0,BY5-Assumptions!$B$91)),IF(BY5<Assumptions!$B$92,MAX(0,(AM6-AP6-BE6-BO6-BQ6)-Assumptions!$B$93)*Assumptions!$B$98,0)) -> 0 | BY6: =BW6+BX6 -> 0 | BZ6: =IF(A6=1,0,CB5) -> 1772 | CA6: =AH6 -> 443 | CB6: =BZ6+CA6 -> 2215 | CC6: =CC5+(G6+J6)/(Salary_Schedule!E6*12/208) -> 1710.4412 | CD6: =CD5+(O6+R6)/(Salary_Schedule!G6*12/208) -> 30.886646 | CE6: =BV6 -> 12414.696 | CF6: =Assumptions!$B$55*(1+Assumptions!$B$56)^((B6-2025)+(A6-1)/12) -> 530425.91 | CG6: =-AT6 -> -392552.29 | CH6: =-(AV6+AX6+BB6+AZ6+BD6+AF6+BG6+BI6) -> -64849.206 | CI6: =CC6*(Salary_Schedule!E6/173.33)*(1-Assumptions!$B$28)+CD6*(Salary_Schedule!G6/173.33)*(1-Assumptions!$B$28) -> 47967.891 | CJ6: =CE6+CF6+CG6+CH6+CI6 -> 133407.01
